
local _ = {name = "air", prob = 0, param2 = 0}
local w = {name = "ethereal:vine", prob = 254, param2 = 2}
local W = {name = "ethereal:vine", prob = 254, param2 = 5}
local v = {name = "ethereal:vine", prob = 254, param2 = 4}
local V = {name = "ethereal:vine", prob = 254, param2 = 3}
local l = {name = "ethereal:mangrove_leaves", prob = 254, param2 = 0}
local t = {name = "ethereal:mangrove_tree", prob = 254, param2 = 8}
local T = {name = "ethereal:mangrove_tree", prob = 254, param2 = 2}
local i = {name = "ethereal:mangrove_tree", prob = 254, param2 = 18}
local I = {name = "ethereal:mangrove_tree", prob = 254, param2 = 0}
local m = {name = "ethereal:mangrove_tree", prob = 254, param2 = 12}
local r = {name = "ethereal:mangrove_roots", prob = 254, param2 = 0}

ethereal.mangrove_tree = {

	size = {x = 10, y = 14, z = 10},

	yslice_prob = {
		{ypos = 7, prob = 127},
		{ypos = 8, prob = 127},
		{ypos = 9, prob = 127},
		{ypos = 10, prob = 127},
		{ypos = 11, prob = 127},
	},

	data = {
		_, _, _, _, _, _, _, _, _, _,
		_, _, _, _, _, _, _, _, _, _,
		_, _, _, _, v, _, _, _, _, _,
		_, _, _, _, v, _, _, _, _, _,
		_, _, _, _, v, _, _, _, _, _,
		_, _, _, _, _, _, _, _, _, _,
		_, _, _, _, _, _, _, _, _, _,
		_, _, _, _, _, _, _, _, _, _,
		_, _, _, _, _, _, _, _, _, _,
		_, _, _, _, _, _, _, _, _, _,
		_, _, _, _, _, _, _, _, _, _,
		_, _, _, _, _, _, _, _, _, _,
		_, _, _, _, _, _, _, _, _, _,
		_, _, _, _, _, _, _, _, _, _,

		_, _, _, _, r, _, _, _, _, _,
		_, _, _, _, r, _, _, _, _, _,
		_, _, v, l, l, l, V, _, _, _,
		_, _, _, _, l, l, V, _, _, _,
		_, _, _, _, l, _, _, _, _, _,
		_, _, _, _, _, _, _, _, _, _,
		_, _, _, _, _, _, _, _, _, _,
		_, _, _, _, _, _, _, _, _, _,
		_, _, _, _, _, _, _, _, _, _,
		_, _, _, _, _, _, _, _, _, _,
		_, _, _, _, _, _, _, _, _, _,
		_, _, _, _, l, _, _, _, _, _,
		_, _, _, _, _, _, _, _, _, _,
		_, _, _, _, _, _, _, _, _, _,

		_, _, _, _, _, _, _, _, _, _,
		_, _, _, _, r, _, _, _, _, _,
		_, v, l, l, t, l, l, _, _, _,
		_, v, _, l, l, l, _, _, _, _,
		_, v, _, _, l, _, _, _, _, _,
		_, _, _, _, _, _, _, _, _, _,
		_, _, _, _, _, _, _, _, _, _,
		_, _, _, _, _, _, _, _, _, _,
		_, _, _, _, l, _, _, _, _, _,
		_, _, _, _, l, _, l, _, _, _,
		_, _, _, _, l, l, _, _, _, _,
		_, _, _, _, l, _, _, _, _, _,
		_, _, _, l, l, _, _, _, _, _,
		_, _, _, _, _, _, _, _, _, _,

		_, _, _, r, r, _, _, _, _, _,
		_, _, _, r, _, _, _, _, _, _,
		w, _, l, l, t, l, l, l, _, _,
		w, _, l, l, l, _, l, V, _, _,
		w, l, l, l, l, l, _, _, _, _,
		_, _, l, l, l, _, _, _, _, _,
		_, _, l, l, l, _, _, _, _, _,
		_, _, _, _, l, _, _, _, _, _,
		_, _, _, l, l, _, _, _, _, _,
		_, _, _, _, l, l, l, _, _, _,
		_, _, _, l, l, l, l, _, _, _,
		_, _, _, l, l, l, _, _, _, _,
		_, _, _, l, l, _, _, _, _, _,
		_, _, _, _, l, _, _, _, _, _,

		_, r, _, _, T, r, _, _, _, _,
		_, r, l, r, T, l, l, l, _, _,
		_, r, l, l, T, i, i, l, V, _,
		_, l, i, i, T, l, l, l, _, _,
		_, l, l, l, T, l, l, _, _, _,
		_, l, l, l, i, l, _, _, _, _,
		_, _, l, l, i, l, _, _, _, _,
		_, _, _, l, i, l, _, _, _, _,
		_, _, l, l, i, l, _, _, _, _,
		_, _, _, l, i, l, l, l, _, _,
		_, _, l, l, i, m, m, l, _, _,
		_, _, _, l, i, l, l, l, _, _,
		_, _, _, l, i, l, _, _, _, _,
		_, _, _, _, l, _, _, _, _, _,

		_, _, _, _, _, _, _, _, _, _,
		_, _, l, l, l, l, l, l, V, _,
		w, _, l, l, l, l, l, _, _, _,
		w, l, l, l, l, l, l, l, V, _,
		w, l, l, l, t, l, l, _, _, _,
		_, l, l, l, l, l, _, _, _, _,
		_, _, _, l, l, l, _, _, _, _,
		_, _, l, l, l, l, _, _, _, _,
		_, _, _, l, l, _, _, _, _, _,
		_, _, _, _, l, l, l, _, _, _,
		_, _, _, l, l, l, l, _, _, _,
		_, _, l, l, l, l, _, _, _, _,
		_, _, l, l, l, l, _, _, _, _,
		_, _, _, _, l, _, _, _, _, _,

		_, _, _, _, _, _, _, _, _, _,
		w, l, _, _, l, _, _, _, _, _,
		w, l, l, l, l, l, l, l, V, _,
		_, l, l, l, l, l, l, _, _, _,
		_, l, l, l, l, l, _, _, _, _,
		_, _, l, l, l, l, _, _, _, _,
		_, _, _, l, _, _, _, _, _, _,
		_, _, _, _, _, _, _, _, _, _,
		_, _, _, l, l, l, _, _, _, _,
		_, _, _, _, _, _, _, _, _, _,
		_, _, _, l, l, _, _, _, _, _,
		_, _, _, l, _, _, _, _, _, _,
		_, _, _, l, l, _, _, _, _, _,
		_, _, _, _, _, _, _, _, _, _,

		_, _, _, _, _, _, _, _, _, _,
		_, _, _, _, _, _, _, _, _, _,
		_, _, _, l, l, l, V, W, _, _,
		_, _, l, l, l, l, _, _, _, _,
		_, _, l, l, l, _, _, _, _, _,
		_, _, _, l, _, _, _, _, _, _,
		_, _, _, _, _, _, _, _, _, _,
		_, _, _, _, _, _, _, _, _, _,
		_, _, _, _, l, _, _, _, _, _,
		_, _, _, _, _, _, _, _, _, _,
		_, _, _, l, _, _, _, _, _, _,
		_, _, _, _, _, _, _, _, _, _,
		_, _, _, _, _, _, _, _, _, _,
		_, _, _, _, _, _, _, _, _, _,

		_, _, _, r, _, _, _, _, _, _,
		_, _, _, r, _, _, _, _, _, _,
		_, _, W, r, _, _, _, _, _, _,
		_, _, W, l, l, _, _, _, _, _,
		_, _, _, l, _, _, _, _, _, _,
		_, _, _, _, _, _, _, _, _, _,
		_, _, _, _, _, _, _, _, _, _,
		_, _, _, _, _, _, _, _, _, _,
		_, _, _, _, _, _, _, _, _, _,
		_, _, _, _, _, _, _, _, _, _,
		_, _, _, _, _, _, _, _, _, _,
		_, _, _, _, _, _, _, _, _, _,
		_, _, _, _, _, _, _, _, _, _,
		_, _, _, _, _, _, _, _, _, _,

		_, _, _, _, _, _, _, _, _, _,
		_, _, _, _, _, _, _, _, _, _,
		_, _, _, _, _, _, _, _, _, _,
		_, _, _, _, W, _, _, _, _, _,
		_, _, _, _, _, _, _, _, _, _,
		_, _, _, _, _, _, _, _, _, _,
		_, _, _, _, _, _, _, _, _, _,
		_, _, _, _, _, _, _, _, _, _,
		_, _, _, _, _, _, _, _, _, _,
		_, _, _, _, _, _, _, _, _, _,
		_, _, _, _, _, _, _, _, _, _,
		_, _, _, _, _, _, _, _, _, _,
		_, _, _, _, _, _, _, _, _, _,
		_, _, _, _, _, _, _, _, _, _,
	},
}



local _ = {name = "air", prob = 0, param2 = 0}
local v = {name = "ethereal:vine", prob = 254, param2 = 4}
local V = {name = "ethereal:vine", prob = 254, param2 = 2}
local w = {name = "ethereal:vine", prob = 254, param2 = 3}
local W = {name = "ethereal:vine", prob = 254, param2 = 5}
local r = {name = "ethereal:mangrove_roots", prob = 254, param2 = 0}
local l = {name = "ethereal:mangrove_leaves", prob = 254, param2 = 0}
local t = {name = "ethereal:mangrove_tree", prob = 254, param2 = 6}
local T = {name = "ethereal:mangrove_tree", prob = 254, param2 = 0}
local i = {name = "ethereal:mangrove_tree", prob = 254, param2 = 12}


ethereal.mangrove_tree_2 = {

	size = {x = 10, y = 10, z = 9},

	yslice_prob = {
		{ypos = 6, prob = 127},
	},

	data = {
		_, _, _, _, _, _, _, _, _, _,
		_, _, _, _, _, _, _, _, _, _,
		_, _, _, _, _, _, _, _, _, _,
		_, _, _, _, _, _, v, _, _, _,
		_, _, _, v, v, v, v, _, _, _,
		_, _, _, v, _, _, _, _, _, _,
		_, _, _, v, _, _, _, _, _, _,
		_, _, _, _, _, _, _, _, _, _,
		_, _, _, _, _, _, _, _, _, _,
		_, _, _, _, _, _, _, _, _, _,

		_, r, _, _, _, _, _, r, _, _,
		_, _, _, _, _, _, _, r, _, _,
		_, _, _, _, _, l, r, _, _, _,
		_, _, _, _, _, l, l, _, _, _,
		_, _, l, l, l, l, l, l, _, _,
		_, _, _, l, _, l, l, l, _, _,
		_, _, l, l, l, l, l, _, _, _,
		_, _, _, _, l, l, l, _, _, _,
		_, _, _, _, _, l, _, _, _, _,
		_, _, _, _, _, _, _, _, _, _,

		_, r, _, _, _, _, _, _, _, _,
		_, r, r, _, _, _, _, _, _, _,
		_, _, r, r, _, _, r, l, _, _,
		_, _, _, r, _, l, r, l, _, _,
		_, _, l, r, l, l, r, l, _, _,
		_, _, _, l, l, l, l, l, _, _,
		_, _, l, l, l, l, l, _, _, _,
		_, _, _, _, l, t, l, _, _, _,
		_, _, _, _, l, l, l, _, _, _,
		_, _, _, _, _, _, _, _, _, _,

		_, _, _, _, _, _, _, _, _, _,
		_, _, _, _, _, _, _, _, _, _,
		_, _, _, _, _, _, _, _, _, _,
		_, _, _, r, l, l, l, l, _, _,
		_, V, l, r, r, r, r, l, l, _,
		_, V, l, l, l, l, l, _, _, _,
		_, V, l, l, _, l, l, _, _, _,
		_, _, _, V, l, t, l, _, _, _,
		_, _, _, _, l, l, v, _, _, _,
		_, _, _, _, _, _, v, _, _, _,

		_, _, _, _, _, _, _, _, _, _,
		_, _, _, _, _, _, _, _, _, _,
		_, _, _, _, _, _, r, l, _, _,
		_, _, _, _, _, l, r, l, _, _,
		_, V, l, r, r, T, r, l, l, w,
		_, V, l, i, i, T, l, l, w, _,
		_, _, V, l, l, T, l, w, _, _,
		_, _, _, V, l, T, l, w, _, _,
		_, _, _, V, l, T, l, w, _, _,
		_, _, _, V, l, l, l, w, _, _,

		_, _, _, _, _, _, _, r, _, _,
		_, _, _, _, _, _, _, r, _, _,
		_, _, _, _, _, _, r, _, _, _,
		_, _, r, _, _, l, l, l, _, _,
		_, V, l, r, r, r, r, l, _, _,
		_, _, l, l, l, l, r, l, _, _,
		_, _, _, l, l, l, l, _, _, _,
		_, _, _, V, l, l, l, _, _, _,
		_, _, _, _, l, l, l, _, _, _,
		_, _, _, _, W, l, l, _, _, _,

		_, _, _, _, _, _, _, _, _, _,
		_, _, _, _, _, _, _, _, _, _,
		_, r, r, _, _, _, _, _, _, _,
		_, _, l, r, _, _, _, _, _, _,
		_, _, l, l, l, l, l, l, _, _,
		_, _, _, _, l, W, l, l, _, _,
		_, _, _, _, W, _, _, _, _, _,
		_, _, _, _, W, _, _, _, _, _,
		_, _, _, _, W, _, _, _, _, _,
		_, _, _, _, _, _, _, _, _, _,

		r, r, _, _, _, _, _, _, _, _,
		_, r, _, _, _, _, _, _, _, _,
		_, _, r, _, _, _, _, _, _, _,
		_, _, _, _, _, _, _, _, _, _,
		_, _, _, W, W, W, W, W, _, _,
		_, _, _, _, W, _, _, _, _, _,
		_, _, _, _, _, _, _, _, _, _,
		_, _, _, _, _, _, _, _, _, _,
		_, _, _, _, _, _, _, _, _, _,
		_, _, _, _, _, _, _, _, _, _,

		_, _, _, _, _, _, _, _, _, _,
		_, _, _, _, _, _, _, _, _, _,
		_, _, _, _, _, _, _, _, _, _,
		_, _, _, _, _, _, _, _, _, _,
		_, _, _, _, _, _, _, _, _, _,
		_, _, _, _, _, _, _, _, _, _,
		_, _, _, _, _, _, _, _, _, _,
		_, _, _, _, _, _, _, _, _, _,
		_, _, _, _, _, _, _, _, _, _,
		_, _, _, _, _, _, _, _, _, _,
	},
}
